<?xml version="1.0" encoding="utf-8"?>
<!-- =================================================================================== -->
<!-- |    This document was autogenerated by xacro from mrobot_with_sick_tim571.urdf.xacro | -->
<!-- |    EDITING THIS FILE BY HAND IS NOT RECOMMENDED                                 | -->
<!-- =================================================================================== -->
<robot name="mrobot">
  <!-- Defining the colors used in this robot -->
  <material name="Black">
    <color rgba="0 0 0 1"/>
  </material>
  <material name="White">
    <color rgba="1 1 1 1"/>
  </material>
  <material name="Blue">
    <color rgba="0 0 1 1"/>
  </material>
  <material name="Red">
    <color rgba="1 0 0 1"/>
  </material>
  <link name="base_footprint">
    <visual>
      <origin rpy="0 0 0" xyz="0 0 0"/>
      <geometry>
        <box size="0.001 0.001 0.001"/>
      </geometry>
    </visual>
  </link>
  <joint name="base_footprint_joint" type="fixed">
    <origin rpy="0 0 0" xyz="0 0 0.033"/>
    <parent link="base_footprint"/>
    <child link="base_link"/>
  </joint>
  <!-- BASE-LINK -->
  <!--Actual body/chassis of the robot-->
  <link name="base_link">
    <inertial>
      <mass value="0.5"/>
      <inertia ixx="0.00211354166667" ixy="0" ixz="0" iyy="0.00211354166667" iyz="0" izz="0.004225"/>
    </inertial>
    <visual>
      <origin rpy="0 0 0" xyz=" 0 0 0"/>
      <geometry>
        <cylinder length="0.005" radius="0.13"/>
      </geometry>
      <material name="yellow"/>
    </visual>
    <collision>
      <origin rpy="0 0 0" xyz="0 0 0"/>
      <geometry>
        <cylinder length="0.005" radius="0.13"/>
      </geometry>
    </collision>
  </link>
  <gazebo reference="base_link">
    <material>Gazebo/Blue</material>
  </gazebo>
  <!-- lr: left, right -->
  <link name="wheel_right_link">
    <visual>
      <origin rpy="1.57079632679 0  0 " xyz="0 0 0"/>
      <geometry>
        <cylinder length="0.017" radius="0.033"/>
      </geometry>
      <material name="Black"/>
    </visual>
    <collision>
      <origin rpy="1.57079632679 0 0 " xyz="0 0 0"/>
      <geometry>
        <cylinder length="0.017" radius="0.033"/>
      </geometry>
    </collision>
    <inertial>
      <mass value="0.1"/>
      <inertia ixx="2.96333333333e-05" ixy="0" ixz="0" iyy="2.96333333333e-05" iyz="0" izz="5.445e-05"/>
    </inertial>
  </link>
  <gazebo reference="wheel_right_link">
    <material>Gazebo/Black</material>
  </gazebo>
  <joint name="base_to_wheel_right_joint" type="continuous">
    <parent link="base_link"/>
    <child link="wheel_right_link"/>
    <origin rpy="0 0 0" xyz="-0.05 0.13 0"/>
    <axis rpy="0  0" xyz="0 1 0"/>
  </joint>
  <!-- Transmission is important to link the joints and the controller -->
  <transmission name="wheel_right_joint_trans">
    <type>transmission_interface/SimpleTransmission</type>
    <joint name="base_to_wheel_right_joint"/>
    <actuator name="wheel_right_joint_motor">
      <hardwareInterface>VelocityJointInterface</hardwareInterface>
      <mechanicalReduction>1</mechanicalReduction>
    </actuator>
  </transmission>
  <!-- lr: left, right -->
  <link name="wheel_left_link">
    <visual>
      <origin rpy="1.57079632679 0  0 " xyz="0 0 0"/>
      <geometry>
        <cylinder length="0.017" radius="0.033"/>
      </geometry>
      <material name="Black"/>
    </visual>
    <collision>
      <origin rpy="1.57079632679 0 0 " xyz="0 0 0"/>
      <geometry>
        <cylinder length="0.017" radius="0.033"/>
      </geometry>
    </collision>
    <inertial>
      <mass value="0.1"/>
      <inertia ixx="2.96333333333e-05" ixy="0" ixz="0" iyy="2.96333333333e-05" iyz="0" izz="5.445e-05"/>
    </inertial>
  </link>
  <gazebo reference="wheel_left_link">
    <material>Gazebo/Black</material>
  </gazebo>
  <joint name="base_to_wheel_left_joint" type="continuous">
    <parent link="base_link"/>
    <child link="wheel_left_link"/>
    <origin rpy="0 0 0" xyz="-0.05 -0.13 0"/>
    <axis rpy="0  0" xyz="0 1 0"/>
  </joint>
  <!-- Transmission is important to link the joints and the controller -->
  <transmission name="wheel_left_joint_trans">
    <type>transmission_interface/SimpleTransmission</type>
    <joint name="base_to_wheel_left_joint"/>
    <actuator name="wheel_left_joint_motor">
      <hardwareInterface>VelocityJointInterface</hardwareInterface>
      <mechanicalReduction>1</mechanicalReduction>
    </actuator>
  </transmission>
  <!-- fb: front, back -->
  <link name="front_caster_link">
    <visual>
      <origin rpy="0 0 0" xyz="0 0 0 "/>
      <geometry>
        <sphere radius="0.016"/>
      </geometry>
      <material name="Black"/>
    </visual>
    <collision>
      <geometry>
        <sphere radius="0.016"/>
      </geometry>
      <origin rpy="0 0 0" xyz="0 0 0 "/>
    </collision>
    <inertial>
      <mass value="0.01"/>
      <inertia ixx="1.024e-06" ixy="0" ixz="0" iyy="1.024e-06" iyz="0" izz="1.024e-06"/>
    </inertial>
  </link>
  <gazebo reference="front_caster_link">
    <material>Gazebo/Black</material>
  </gazebo>
  <joint name="base_to_front_caster_joint" type="fixed">
    <parent link="base_link"/>
    <child link="front_caster_link"/>
    <origin rpy="0 0 0" xyz="0.12 0 -0.016"/>
  </joint>
  <joint name="standoff_2in_1_joint" type="fixed">
    <origin rpy="0 0 0" xyz="-0.09 -0.07 0.035"/>
    <parent link="base_link"/>
    <child link="standoff_2in_1_link"/>
  </joint>
  <link name="standoff_2in_1_link">
    <inertial>
      <mass value="0.001"/>
      <origin xyz="0 0 0"/>
      <inertia ixx="0.0001" ixy="0.0" ixz="0.0" iyy="0.0001" iyz="0.0" izz="0.0001"/>
    </inertial>
    <visual>
      <origin rpy="0 0 0" xyz=" 0 0 0 "/>
      <geometry>
        <box size="0.01 0.01 0.07"/>
      </geometry>
      <material name="black">
        <color rgba="0.16 0.17 0.15 0.9"/>
      </material>
    </visual>
    <collision>
      <origin rpy="0 0 0" xyz="0.0 0.0 0.0"/>
      <geometry>
        <box size="0.01 0.01 0.07"/>
      </geometry>
    </collision>
  </link>
  <joint name="standoff_2in_2_joint" type="fixed">
    <origin rpy="0 0 0" xyz="-0.09 0.07 0.035"/>
    <parent link="base_link"/>
    <child link="standoff_2in_2_link"/>
  </joint>
  <link name="standoff_2in_2_link">
    <inertial>
      <mass value="0.001"/>
      <origin xyz="0 0 0"/>
      <inertia ixx="0.0001" ixy="0.0" ixz="0.0" iyy="0.0001" iyz="0.0" izz="0.0001"/>
    </inertial>
    <visual>
      <origin rpy="0 0 0" xyz=" 0 0 0 "/>
      <geometry>
        <box size="0.01 0.01 0.07"/>
      </geometry>
      <material name="black">
        <color rgba="0.16 0.17 0.15 0.9"/>
      </material>
    </visual>
    <collision>
      <origin rpy="0 0 0" xyz="0.0 0.0 0.0"/>
      <geometry>
        <box size="0.01 0.01 0.07"/>
      </geometry>
    </collision>
  </link>
  <joint name="standoff_2in_3_joint" type="fixed">
    <origin rpy="0 0 0" xyz="0.06 -0.1 0.035"/>
    <parent link="base_link"/>
    <child link="standoff_2in_3_link"/>
  </joint>
  <link name="standoff_2in_3_link">
    <inertial>
      <mass value="0.001"/>
      <origin xyz="0 0 0"/>
      <inertia ixx="0.0001" ixy="0.0" ixz="0.0" iyy="0.0001" iyz="0.0" izz="0.0001"/>
    </inertial>
    <visual>
      <origin rpy="0 0 0" xyz=" 0 0 0 "/>
      <geometry>
        <box size="0.01 0.01 0.07"/>
      </geometry>
      <material name="black">
        <color rgba="0.16 0.17 0.15 0.9"/>
      </material>
    </visual>
    <collision>
      <origin rpy="0 0 0" xyz="0.0 0.0 0.0"/>
      <geometry>
        <box size="0.01 0.01 0.07"/>
      </geometry>
    </collision>
  </link>
  <joint name="standoff_2in_4_joint" type="fixed">
    <origin rpy="0 0 0" xyz="0.06 0.1 0.035"/>
    <parent link="base_link"/>
    <child link="standoff_2in_4_link"/>
  </joint>
  <link name="standoff_2in_4_link">
    <inertial>
      <mass value="0.001"/>
      <origin xyz="0 0 0"/>
      <inertia ixx="0.0001" ixy="0.0" ixz="0.0" iyy="0.0001" iyz="0.0" izz="0.0001"/>
    </inertial>
    <visual>
      <origin rpy="0 0 0" xyz=" 0 0 0 "/>
      <geometry>
        <box size="0.01 0.01 0.07"/>
      </geometry>
      <material name="black">
        <color rgba="0.16 0.17 0.15 0.9"/>
      </material>
    </visual>
    <collision>
      <origin rpy="0 0 0" xyz="0.0 0.0 0.0"/>
      <geometry>
        <box size="0.01 0.01 0.07"/>
      </geometry>
    </collision>
  </link>
  <joint name="standoff_2in_5_joint" type="fixed">
    <origin rpy="0 0 0" xyz="0 0 0.07"/>
    <parent link="standoff_2in_1_link"/>
    <child link="standoff_2in_5_link"/>
  </joint>
  <link name="standoff_2in_5_link">
    <inertial>
      <mass value="0.001"/>
      <origin xyz="0 0 0"/>
      <inertia ixx="0.0001" ixy="0.0" ixz="0.0" iyy="0.0001" iyz="0.0" izz="0.0001"/>
    </inertial>
    <visual>
      <origin rpy="0 0 0" xyz=" 0 0 0 "/>
      <geometry>
        <box size="0.01 0.01 0.07"/>
      </geometry>
      <material name="black">
        <color rgba="0.16 0.17 0.15 0.9"/>
      </material>
    </visual>
    <collision>
      <origin rpy="0 0 0" xyz="0.0 0.0 0.0"/>
      <geometry>
        <box size="0.01 0.01 0.07"/>
      </geometry>
    </collision>
  </link>
  <joint name="standoff_2in_6_joint" type="fixed">
    <origin rpy="0 0 0" xyz="0 0 0.07"/>
    <parent link="standoff_2in_2_link"/>
    <child link="standoff_2in_6_link"/>
  </joint>
  <link name="standoff_2in_6_link">
    <inertial>
      <mass value="0.001"/>
      <origin xyz="0 0 0"/>
      <inertia ixx="0.0001" ixy="0.0" ixz="0.0" iyy="0.0001" iyz="0.0" izz="0.0001"/>
    </inertial>
    <visual>
      <origin rpy="0 0 0" xyz=" 0 0 0 "/>
      <geometry>
        <box size="0.01 0.01 0.07"/>
      </geometry>
      <material name="black">
        <color rgba="0.16 0.17 0.15 0.9"/>
      </material>
    </visual>
    <collision>
      <origin rpy="0 0 0" xyz="0.0 0.0 0.0"/>
      <geometry>
        <box size="0.01 0.01 0.07"/>
      </geometry>
    </collision>
  </link>
  <joint name="standoff_2in_7_joint" type="fixed">
    <origin rpy="0 0 0" xyz="0 0 0.07"/>
    <parent link="standoff_2in_3_link"/>
    <child link="standoff_2in_7_link"/>
  </joint>
  <link name="standoff_2in_7_link">
    <inertial>
      <mass value="0.001"/>
      <origin xyz="0 0 0"/>
      <inertia ixx="0.0001" ixy="0.0" ixz="0.0" iyy="0.0001" iyz="0.0" izz="0.0001"/>
    </inertial>
    <visual>
      <origin rpy="0 0 0" xyz=" 0 0 0 "/>
      <geometry>
        <box size="0.01 0.01 0.07"/>
      </geometry>
      <material name="black">
        <color rgba="0.16 0.17 0.15 0.9"/>
      </material>
    </visual>
    <collision>
      <origin rpy="0 0 0" xyz="0.0 0.0 0.0"/>
      <geometry>
        <box size="0.01 0.01 0.07"/>
      </geometry>
    </collision>
  </link>
  <joint name="standoff_2in_8_joint" type="fixed">
    <origin rpy="0 0 0" xyz="0 0 0.07"/>
    <parent link="standoff_2in_4_link"/>
    <child link="standoff_2in_8_link"/>
  </joint>
  <link name="standoff_2in_8_link">
    <inertial>
      <mass value="0.001"/>
      <origin xyz="0 0 0"/>
      <inertia ixx="0.0001" ixy="0.0" ixz="0.0" iyy="0.0001" iyz="0.0" izz="0.0001"/>
    </inertial>
    <visual>
      <origin rpy="0 0 0" xyz=" 0 0 0 "/>
      <geometry>
        <box size="0.01 0.01 0.07"/>
      </geometry>
      <material name="black">
        <color rgba="0.16 0.17 0.15 0.9"/>
      </material>
    </visual>
    <collision>
      <origin rpy="0 0 0" xyz="0.0 0.0 0.0"/>
      <geometry>
        <box size="0.01 0.01 0.07"/>
      </geometry>
    </collision>
  </link>
  <link name="plate_1_link">
    <inertial>
      <mass value="0.1"/>
      <inertia ixx="0.000422708333333" ixy="0" ixz="0" iyy="0.000422708333333" iyz="0" izz="0.000845"/>
    </inertial>
    <visual>
      <origin rpy="0 0 0" xyz=" 0 0 0 "/>
      <geometry>
        <cylinder length="0.005" radius="0.13"/>
      </geometry>
      <material name="yellow"/>
    </visual>
    <collision>
      <origin rpy="0 0 0" xyz="0.0 0.0 0.0"/>
      <geometry>
        <cylinder length="0.005" radius="0.13"/>
      </geometry>
    </collision>
  </link>
  <gazebo reference="plate_1_link">
    <material>Gazebo/Blue</material>
  </gazebo>
  <joint name="plate_1_joint" type="fixed">
    <origin rpy="0 0 0" xyz="0 0 0.07"/>
    <parent link="base_link"/>
    <child link="plate_1_link"/>
  </joint>
  <link name="plate_2_link">
    <inertial>
      <mass value="0.1"/>
      <inertia ixx="0.000422708333333" ixy="0" ixz="0" iyy="0.000422708333333" iyz="0" izz="0.000845"/>
    </inertial>
    <visual>
      <origin rpy="0 0 0" xyz=" 0 0 0 "/>
      <geometry>
        <cylinder length="0.005" radius="0.13"/>
      </geometry>
      <material name="yellow"/>
    </visual>
    <collision>
      <origin rpy="0 0 0" xyz="0.0 0.0 0.0"/>
      <geometry>
        <cylinder length="0.005" radius="0.13"/>
      </geometry>
    </collision>
  </link>
  <gazebo reference="plate_2_link">
    <material>Gazebo/Blue</material>
  </gazebo>
  <joint name="plate_2_joint" type="fixed">
    <origin rpy="0 0 0" xyz="0 0 0.07"/>
    <parent link="plate_1_link"/>
    <child link="plate_2_link"/>
  </joint>
  <!-- controller -->
  <gazebo>
    <plugin filename="libgazebo_ros_diff_drive.so" name="differential_drive_controller">
      <rosDebugLevel>Debug</rosDebugLevel>
      <publishWheelTF>true</publishWheelTF>
      <robotNamespace>/</robotNamespace>
      <publishTf>1</publishTf>
      <publishWheelJointState>true</publishWheelJointState>
      <alwaysOn>true</alwaysOn>
      <updateRate>100.0</updateRate>
      <legacyMode>true</legacyMode>
      <leftJoint>base_to_wheel_left_joint</leftJoint>
      <rightJoint>base_to_wheel_right_joint</rightJoint>
      <wheelSeparation>0.26</wheelSeparation>
      <wheelDiameter>0.066</wheelDiameter>
      <broadcastTF>1</broadcastTF>
      <wheelTorque>30</wheelTorque>
      <wheelAcceleration>1.8</wheelAcceleration>
      <commandTopic>cmd_vel</commandTopic>
      <odometryFrame>odom</odometryFrame>
      <odometryTopic>odom</odometryTopic>
      <robotBaseFrame>base_footprint</robotBaseFrame>
    </plugin>
  </gazebo>
  <!-- Attach the Kinect -->
  <joint name="sicktim571_joint" type="fixed">
    <origin rpy="0 0 0" xyz="0 0 0"/>
    <parent link="plate_2_link"/>
    <child link="laser_mount_link"/>
  </joint>
  <!-- z_offset: distance between base plate and laser center (= center of mesh) -->
  <link name="laser_mount_link">
    <inertial>
      <mass value="0.001"/>
      <origin xyz="0 0 0"/>
      <inertia ixx="0.000001" ixy="0.0" ixz="0.0" iyy="0.000001" iyz="0.0" izz="0.000001"/>
    </inertial>
  </link>
  <joint name="laser_joint" type="fixed">
    <parent link="laser_mount_link"/>
    <child link="laser"/>
    <origin rpy="0 0 0" xyz="0 0 0.06296"/>
  </joint>
  <link name="laser">
    <visual>
      <geometry>
        <mesh filename="package://sick_tim/meshes/sick_tim551.stl"/>
      </geometry>
      <material name="blue">
        <color rgba="0 0 1 1"/>
      </material>
    </visual>
    <collision>
      <geometry>
        <mesh filename="package://sick_tim/meshes/sick_tim551.stl"/>
      </geometry>
    </collision>
    <inertial>
      <mass value="0.25"/>
      <origin xyz="0 0 -0.026"/>
      <inertia ixx="0.0002290832417" ixy="0.0" ixz="0.0" iyy="0.0002290832417" iyz="0.0" izz="0.00014999994"/>
    </inertial>
  </link>
  <gazebo reference="laser">
    <material value="Gazebo/Black"/>
    <sensor name="laser" type="ray">
      <always_on>true</always_on>
      <update_rate>15.0</update_rate>
      <pose>0 0 0 0 0 0</pose>
      <visualize>false</visualize>
      <ray>
        <scan>
          <horizontal>
            <samples>271</samples>
            <resolution>1</resolution>
            <min_angle>-2.357</min_angle>
            <max_angle>2.357</max_angle>
          </horizontal>
        </scan>
        <range>
          <min>0.4</min>
          <max>10</max>
          <resolution>0.01</resolution>
        </range>
      </ray>
      <plugin filename="libgazebo_ros_laser.so" name="gazebo_ros_laser_controller">
        <gaussianNoise>0.005</gaussianNoise>
        <alwaysOn>true</alwaysOn>
        <updateRate>15.0</updateRate>
        <topicName>/scan</topicName>
        <frameName>laser</frameName>
      </plugin>
    </sensor>
  </gazebo>
</robot>

